Workbook

Sheet Problemas
A1: Data Profiling — Problemas de Qualidade dos Dados (MoreRhythm)
A2: ARMDD 2026/27 · Grupo 1231274 / 1260541 · Fonte: Data Profiling Task (SSIS) + consultas SQL · Preencher uma linha por problema (colunas B a M). Ver folhas Guia e Notas.
A4: ID | B4: Tabela | C4: Coluna | D4: Perfil / origem | E4: Problema detetado | F4: Exemplo (valor / registo) | G4: Nº registos afetados | H4: Tipo de problema | I4: Gravidade | J4: Correção automatizável? | K4: Ação de limpeza / transformação proposta | L4: Destino do registo | M4: Observações
A5: =IF(B5="","",COUNTA($B$5:B5)) -> 1 | B5: customers | C5: name / taxpayer_number / BBAN / email / phone / contact / address | D5: Column Value Distribution + Candidate Key | E5: Cliente registado em duplicado com identificadores diferentes (cópia exata de todos os atributos) | F5: Clientes 10 e 18 – "Eira e Beira, lda", NIF 502323434 | G5: 2 | H5: Duplicado exato | I5: Alta | J5: Sim | K5: Agrupar os registos duplicados, manter um registo sobrevivente e guardar na Staging Area o mapeamento ID eliminado → ID sobrevivente | L5: Corrigir no ETL | M5: Confirmado pelo Candidate Key (name e taxpayer_number com 96,15% de unicidade). A fatura do cliente 18 tem de ser associada ao cliente sobrevivente.
A6: =IF(B6="","",COUNTA($B$5:B6)) -> 2 | B6: customers | C6: name / taxpayer_number / address / BBAN | D6: Column Value Distribution | E6: Cliente duplicado com dados aproximadamente iguais: nome escrito de forma diferente, NIF com dígitos trocados e morada abreviada; BBAN e código postal iguais | F6: Clientes 8 e 22 – "Luz e Som, lda" vs "Luz e Som Lda."; NIF 365564344 vs 365564434 | G6: 2 | H6: Duplicado aproximado | I6: Alta | J6: Sim | K6: Fuzzy Grouping (SSIS) sobre nome, morada, código postal, telefone e NIF; manter o sobrevivente, completar atributos em falta com o outro registo e guardar o mapeamento de IDs | L6: Corrigir no ETL | M6: O cliente 22 tem telefone e o 8 tem email: ao fundir, aproveitar a informação dos dois. 1 fatura associada ao cliente 22.
A7: =IF(B7="","",COUNTA($B$5:B7)) -> 3 | B7: customers | C7: name / taxpayer_number / address / clity / email | D7: Column Value Distribution | E7: Cliente duplicado com dados aproximadamente iguais: nome abreviado, NIF com dígitos trocados, morada com pontuação diferente, localidade mal escrita; telefone e código postal iguais | F7: Clientes 5 e 26 – "Coro Nossa Senhora Assunção" vs "Coro N. Senhora Assunção"; NIF 300455644 vs 300456544 | G7: 2 | H7: Duplicado aproximado | I7: Alta | J7: Sim | K7: Fuzzy Grouping (SSIS) sobre nome, morada, código postal, telefone e NIF; manter o sobrevivente, completar atributos em falta e guardar o mapeamento de IDs | L7: Corrigir no ETL | M7: Não detetável pelo BBAN (cliente 26 sem BBAN). O 26 foi criado primeiro (31/01/2025) e tem email válido e telemóvel; o 5 tem BBAN. 2 faturas associadas ao cliente 26.
A8: =IF(B8="","",COUNTA($B$5:B8)) -> 4 | B8: customers | C8: zone | D8: Column Null Ratio | E8: Zona em falta (NULL): impede as análises por zona do cliente (1, 6, 9 e 10) | F8: Clientes 2 ("Vendas a Dinheiro") e 20 ("MaisRitmo (interno)") | G8: 2 | H8: Valor em falta | I8: Média | J8: Sim | K8: Associar ao membro "Desconhecido" da dimensão (zona N/D) | L8: Corrigir no ETL | M8: Clientes especiais (genérico e interno). Todos os restantes códigos de zona existem na tabela zones.
A9: =IF(B9="","",COUNTA($B$5:B9)) -> 5 | B9: customers | C9: zip_code / clity | D9: Column Value Distribution | E9: A cidade está embutida no zip_code (código postal + cidade no mesmo campo) e a coluna clity contém o bairro/localidade e não a cidade | F9: "2600-011 VILA FRANCA DE XIRA" com clity "A-dos-Bispos" (cliente 1) | G9: 24 | H9: Inconsistência entre atributos | I9: Alta | J9: Sim | K9: Separar o zip_code em CódigoPostal e Cidade (texto após o código postal); manter clity como Localidade | L9: Corrigir no ETL | M9: Afeta as análises 2 e 8 (cidade do cliente). Usar a clity como cidade daria resultados errados.
A10: =IF(B10="","",COUNTA($B$5:B10)) -> 6 | B10: customers | C10: zip_code | D10: Column Value Distribution | E10: Código postal em falta (string vazia/espaço): não é possível obter a cidade | F10: Clientes 2 e 20 | G10: 2 | H10: Valor em falta | I10: Baixa | J10: Sim | K10: TRIM + converter vazio em NULL: NULLIF(LTRIM(RTRIM(zip_code)), ''); cidade = "Desconhecido" | L10: Corrigir no ETL | M10: Clientes especiais (genérico e interno).
A11: =IF(B11="","",COUNTA($B$5:B11)) -> 7 | B11: customers | C11: zip_code | D11: Column Value Distribution + Column Pattern | E11: Código postal em formato estrangeiro: não segue o padrão \d{4}-\d{3} CIDADE (96% dos registos) | F11: "28108 Alcobendas - Madrid, España" (cliente 21) | G11: 1 | H11: Formato inválido | I11: Média | J11: Sim | K11: Regra de extração por país (zona 5 = Espanha): código de 5 dígitos e cidade antes de " - "; país derivado da zona | L11: Corrigir no ETL | M11: Com a expansão para a UE e Reino Unido, a regra tem de suportar formatos de outros países.
A12: =IF(B12="","",COUNTA($B$5:B12)) -> 8 | B12: customers | C12: clity | D12: Column Value Distribution | E12: Grafia inconsistente da mesma localidade (sem acento e sem "do") | F12: "Bairro Alem Rio" (cliente 26) vs "Bairro Além do Rio" (clientes 5 e 15) | G12: 1 | H12: Grafia inconsistente | I12: Baixa | J12: Sim | K12: Tabela de mapeamento de valores ou Fuzzy Lookup para normalizar a grafia | L12: Corrigir no ETL | M12: O registo 26 é duplicado do 5; com a deduplicação o valor errado pode desaparecer.
A13: =IF(B13="","",COUNTA($B$5:B13)) -> 9 | B13: customers | C13: clity | D13: Column Value Distribution | E13: Localidade em falta (string vazia/espaço) | F13: Clientes 2, 20 e 21 | G13: 3 | H13: Valor em falta | I13: Baixa | J13: Sim | K13: TRIM + converter vazio em NULL: NULLIF(LTRIM(RTRIM(clity)), '') | L13: Corrigir no ETL
A14: =IF(B14="","",COUNTA($B$5:B14)) -> 10 | B14: customers | C14: address | D14: Column Value Distribution | E14: Morada em falta (string vazia/espaço) | F14: Clientes 2 e 20 | G14: 2 | H14: Valor em falta | I14: Baixa | J14: Sim | K14: TRIM + converter vazio em NULL: NULLIF(LTRIM(RTRIM(address)), '') | L14: Corrigir no ETL | M14: Clientes especiais (genérico e interno).
A15: =IF(B15="","",COUNTA($B$5:B15)) -> 11 | B15: customers | C15: taxpayer_number | D15: Column Value Distribution + Column Length Distribution | E15: NIF vazio ou com valor de enchimento, fora do domínio (o NIF português tem 9 dígitos) | F15: "000000000" (cliente 2), vazio (20), "0" (24), "00" (25) | G15: 4 | H15: Violação de domínio | I15: Baixa | J15: Sim | K15: Se o NIF não tiver 9 dígitos ou for só zeros → NULL (ou "N/D") | L15: Corrigir no ETL | M15: O comprimento sozinho não chega: "000000000" tem 9 dígitos. Melhoria possível: validar o dígito de controlo (módulo 11). São clientes especiais (genérico e internos).
A16: =IF(B16="","",COUNTA($B$5:B16)) -> 12 | B16: customers | C16: BBAN | D16: Column Value Distribution + Column Length Distribution | E16: BBAN em falta (string vazia/espaço, não NULL) | F16: Clientes 2, 17, 19, 20, 23, 24, 25 e 26 | G16: 8 | H16: Valor em falta | I16: Baixa | J16: Sim | K16: TRIM + converter vazio em NULL: NULLIF(LTRIM(RTRIM(BBAN)), '') | L16: Corrigir no ETL | M16: O Length Distribution confirma: só existem comprimentos 0 e 21. Nenhuma análise usa o BBAN.
A17: =IF(B17="","",COUNTA($B$5:B17)) -> 13 | B17: customers | C17: email | D17: Column Pattern | E17: Email sem "@" (formato inválido) | F17: "coro.sapo.pt" (cliente 5) | G17: 1 | H17: Formato inválido | I17: Baixa | J17: Não | K17: Validar o formato do email no ETL; se for inválido → NULL | L17: Corrigir no ETL | M17: O mesmo cliente tem um registo duplicado (cliente 26) com o email correto "coro@sapo.pt"; com a deduplicação pode ficar o email válido.
A18: =IF(B18="","",COUNTA($B$5:B18)) -> 14 | B18: customers | C18: email | D18: Column Value Distribution | E18: Email em falta (string vazia/espaço) | F18: Clientes 2, 7, 9, 12, 13, 14, 17, 20, 21, 22, 24 e 25 | G18: 12 | H18: Valor em falta | I18: Baixa | J18: Sim | K18: TRIM + converter vazio em NULL: NULLIF(LTRIM(RTRIM(email)), '') | L18: Corrigir no ETL
A19: =IF(B19="","",COUNTA($B$5:B19)) -> 15 | B19: customers | C19: phone / mobile | D19: Column Pattern | E19: Formato de telefone inconsistente: com e sem espaços e com indicativo internacional | F19: "245 475 457", "213 83 34 18", "+34 914 902 444" (phone); "911 234 432" (mobile) | G19: 9 | H19: Formato inválido | I19: Baixa | J19: Sim | K19: Remover espaços e normalizar o indicativo internacional (ex.: +34 em campo próprio ou prefixo padronizado) | L19: Corrigir no ETL | M19: phone: clientes 10, 16, 17, 18, 19, 21, 22, 23 · mobile: cliente 19.
A20: =IF(B20="","",COUNTA($B$5:B20)) -> 16 | B20: customers | C20: phone | D20: Column Value Distribution | E20: Telefone em falta (string vazia/espaço) | F20: Clientes 2, 7, 8, 9, 15, 20, 24 e 25 | G20: 8 | H20: Valor em falta | I20: Baixa | J20: Sim | K20: TRIM + converter vazio em NULL: NULLIF(LTRIM(RTRIM(phone)), '') | L20: Corrigir no ETL
A21: =IF(B21="","",COUNTA($B$5:B21)) -> 17 | B21: customers | C21: mobile | D21: Column Value Distribution | E21: Telemóvel em falta (string vazia/espaço) | F21: 21 dos 26 clientes (só 1, 3, 6, 19 e 26 têm valor) | G21: 21 | H21: Valor em falta | I21: Baixa | J21: Sim | K21: TRIM + converter vazio em NULL: NULLIF(LTRIM(RTRIM(mobile)), '') | L21: Corrigir no ETL
A22: =IF(B22="","",COUNTA($B$5:B22)) -> 18 | B22: customers | C22: contact | D22: Column Value Distribution | E22: Pessoa de contacto em falta (string vazia/espaço) | F22: Clientes 2, 9, 11, 12, 13, 19, 20, 21, 23, 24, 25 e 26 | G22: 12 | H22: Valor em falta | I22: Baixa | J22: Sim | K22: TRIM + converter vazio em NULL: NULLIF(LTRIM(RTRIM(contact)), '') | L22: Corrigir no ETL
A23: =IF(B23="","",COUNTA($B$5:B23)) -> 19 | B23: customers | C23: seller | D23: Column Value Distribution + Consulta SQL | E23: Código de vendedor sem integridade referencial: não existe FK para employees; o valor 0 não corresponde a nenhum funcionário e os valores 1 e 2 apontam para funcionários que não são vendedores | F23: seller = 0 nos clientes 2, 20, 24 e 25 | G23: 4 | H23: Integridade referencial | I23: Baixa | J23: Não | K23: Não usar como ligação à dimensão de funcionários; manter só como atributo descritivo ou excluir do data mart | L23: Manter / sem ação | M23: O funcionário da venda vem de invoices.employee (com FK declarada), que é o usado nas análises 3 e 4.
A24: =IF(B24="","",COUNTA($B$5:B24)) -> 20 | B24: customers | C24: type | D24: Column Value Distribution | E24: Clientes que não são clientes reais de vendas: entidades internas e cliente genérico de vendas a dinheiro | F24: "Interno": clientes 20, 24 e 25; "Vendas a Dinheiro" (cliente 2) classificado como "Cliente Final" | G24: 4 | H24: Regra de negócio | I24: Média | J24: Não | K24: Decidir no modelo dimensional se as vendas a clientes internos entram nas análises (ex.: flag ClienteInterno na DimCustomer) | L24: Manter / sem ação | M24: Os 4 valores de type estão escritos de forma consistente. As contagens por tipo estão inflacionadas pelos duplicados.
A25: =IF(B25="","",COUNTA($B$5:B25)) -> 21 | B25: invoices_lines | C25: quantity | D25: Column Statistics + Consulta SQL | E25: Quantidade negativa numa venda (erro de sinal): line_total e line_vat são positivos e coerentes com os totais da fatura | F25: V002 com quantity = -2 (fatura ADM06013159093,354502931); G001 com quantity = -1 (fatura ADM06022868091,750385884) | G25: 2 | H25: Violação de domínio | I25: Alta | J25: Sim | K25: Se |quantity| × |unit_price| = line_total e o IVA for coerente → corrigir com ABS(quantity); caso contrário → tabela de erros | L25: Corrigir no ETL | M25: Não são devoluções: as faturas têm totais positivos que já contam estas linhas com sinal positivo. Detetado também pela consulta a) (sinal de quantity × unit_price diferente do de line_total).
A26: =IF(B26="","",COUNTA($B$5:B26)) -> 22 | B26: invoices_lines | C26: unit_price | D26: Column Statistics + Consulta SQL | E26: Preço unitário negativo numa venda (erro de sinal): line_total e line_vat são positivos | F26: ECPOCKI com unit_price = -140 (fatura ADM06013159092,572514309); P001 com unit_price = -13 (fatura ADM06033159385,916951128) | G26: 2 | H26: Violação de domínio | I26: Alta | J26: Sim | K26: Se |quantity| × |unit_price| = line_total e o IVA for coerente → corrigir com ABS(unit_price); caso contrário → tabela de erros | L26: Corrigir no ETL | M26: Na fatura ADM06013159092,572514309 o products_total (145) não coincide com a linha (140), embora o IVA da fatura (32,20) seja o da linha: o problema está no total da fatura (ver análise da invoices).
A27: =IF(B27="","",COUNTA($B$5:B27)) -> 23 | B27: invoices_lines | C27: unit_price | D27: Consulta SQL | E27: Preço de venda diferente do preço atual do produto (products.current_sell_price ÷ 10^6) | F27: 9 linhas abaixo do preço atual (−1,6% a −5,45%, ex.: G002 a 1111 vs 1175); 1 acima (B004 a 76 vs 71, +7,04%) | G27: 10 | H27: Regra de negócio | I27: Baixa | J27: Não | K27: Usar sempre o unit_price da linha como preço de venda; não derivar preços da tabela products (preço atual, não histórico, e guardado ×10^6) | L27: Manter / sem ação | M27: As diferenças para baixo são compatíveis com descontos ou alterações de preço posteriores à venda. O caso B004 (+7%) coincide com a fatura ADM06022859337,463265852, cujo products_total (234) não bate com a soma das linhas (239): verificar na análise da invoices.
A28: =IF(B28="","",COUNTA($B$5:B28)) -> 24 | B28: invoices_lines | C28: last_update_time | D28: Consulta SQL | E28: A hora da última alteração é sempre igual à hora de criação, mesmo quando a data da última alteração muda | F28: 93 de 93 linhas com last_update_time = create_time; em 90 a last_update_date é diferente da create_date | G28: 93 | H28: Inconsistência entre atributos | I28: Média | J28: Sim | K28: Na carga incremental, detetar alterações pela last_update_date (com margem de segurança e comparação por chave), não apenas por data + hora | L28: Manter / sem ação | M28: A last_update_date das linhas é sempre igual à da fatura respetiva: a alteração é propagada da fatura para as linhas.
A29: =IF(B29="","",COUNTA($B$5:B29)) -> 25 | B29: invoices_lines | C29: create_date | D29: Consulta SQL | E29: Data de criação das linhas diferente da data da fatura | F29: 3 linhas da fatura ADM06022859336,963953449: criadas a 28/02/2025, invoice_date = 31/03/2025 | G29: 3 | H29: Inconsistência entre atributos | I29: Média | J29: Não | K29: A data do facto deve vir de invoices.invoice_date e não das datas de auditoria das linhas | L29: Manter / sem ação | M29: O problema está ao nível da fatura (create_date ≠ invoice_date): ver análise da invoices.
A30: =IF(B30="","",COUNTA($B$5:B30)) -> 26 | B30: invoices_lines | C30: invoice_line_stamp_id / invoice_stamp_id / product | D30: Column Length Distribution + Column Value Distribution | E30: Identificadores char com espaços à direita (comprimento real inferior ao definido) | F30: Stamp ids com 23–24 caracteres úteis em char(25); product com espaços até 18 (ex.: "G001 ") | G30: 93 | H30: Formato inválido | I30: Baixa | J30: Sim | K30: Aplicar RTRIM/TRIM a todos os identificadores antes de Lookups e junções no SSIS | L30: Corrigir no ETL | M30: Os Lookups do SSIS comparam os valores exatamente: sem TRIM, "G001" e "G001 " não coincidem.
A31: =IF(B31="","",COUNTA($B$5:B31)) -> 27 | B31: invoices_lines | C31: invoice_line_stamp_id / invoice_stamp_id | D31: Column Pattern | E31: Identificador com formato diferente dos restantes (prefixo "cq" em minúsculas em vez de "ADM") | F31: Linha "cq08012457265,5800000-4" da fatura "cq08012457245,914597944" | G31: 1 | H31: Formato inválido | I31: Baixa | J31: Não | K31: Manter (é um identificador válido e único); registar a anomalia | L31: Manter / sem ação | M31: O prefixo "cq" é o usado nos documentos de compras (purchases). É também a única fatura emitida fora do último dia do mês (01/05/2025, feriado). Confirmar a origem do documento.
A32: =IF(B32="","",COUNTA($B$5:B32)) -> 28 | B32: invoices | C32: products_total | D32: Consulta SQL | E32: Total dos produtos da fatura diferente da soma das linhas; o IVA da fatura bate com as linhas, mas portes, total para IVA e total final foram calculados sobre o products_total errado | F32: ADM06013159092,572514309: 145 vs 140 nas linhas · ADM06022859337,463265852: 234 vs 239 nas linhas | G32: 2 | H32: Inconsistência entre atributos | I32: Alta | J32: Não | K32: Enviar a fatura e as respetivas linhas para a tabela de erros: corrigir implicaria recalcular portes e total final (valor efetivamente faturado), sem certeza de qual é o valor correto | L32: Tabela de erros (SA) | M32: As linhas estão internamente coerentes (qtd × preço e IVA 23%) e o vat_value da fatura coincide com elas. Em 572514309 a linha tem também o erro de sinal (−140); em 463265852 a linha B004 está 7% acima do preço do produto.
A33: =IF(B33="","",COUNTA($B$5:B33)) -> 29 | B33: invoices | C33: shipping_cost | D33: Consulta SQL | E33: Custo de expedição diferente da regra observada (2,5% do products_total) e incoerente com total_for_vat (total_for_vat ≠ products_total + shipping_cost) | F33: ADM06022868165,094314602: 27,70 (esperado 25,20) · ADM06043059438,135478354: 26,275 (esperado 21,275) | G33: 2 | H33: Inconsistência entre atributos | I33: Alta | J33: Sim | K33: Recalcular shipping_cost = total_for_vat − products_total (os campos total_for_vat e final_total são coerentes entre si e com a regra de 2,5%) | L33: Corrigir no ETL | M33: Diferenças de exatamente +2,50 e +5,00. Os portes são a medida das análises 2 e 9 e vão ser repartidos pelas linhas. A regra dos 2,5% verifica-se nas outras 35 faturas.
A34: =IF(B34="","",COUNTA($B$5:B34)) -> 30 | B34: invoices | C34: invoice_date / create_date | D34: Consulta SQL | E34: Data da fatura posterior à data de criação do registo (fatura e linhas criadas a 28/02 com invoice_date 31/03) | F34: ADM06022859336,963953449 (cliente 15) | G34: 1 | H34: Inconsistência entre atributos | I34: Média | J34: Não | K34: Usar invoice_date como data do facto (data de negócio); registar a anomalia | L34: Manter / sem ação | M34: A diferença muda o mês da venda (fevereiro vs março), o que afeta as análises por mês, trimestre e quadrimestre.
... A44: =IF(B44="","",COUNTA($B$5:B44)) -> 40 | B44: categories | C44: Category | D44: Column Value Distribution | E44: Siglas escritas em minúsculas, de forma inconsistente com a grafia habitual | F44: "Leitor de Cd" e "Leitor de Mp3" (em vez de "Leitor de CD" / "Leitor de MP3") | G44: 2 | H44: Grafia inconsistente | I44: Baixa | J44: Sim | K44: Normalizar através de tabela de mapeamento de valores na transformação | L44: Corrigir no ETL | M44: Problema apenas de apresentação; não afeta agrupamentos nem análises.
A45: =IF(B45="","",COUNTA($B$5:B45))
A46: =IF(B46="","",COUNTA($B$5:B46))
A47: =IF(B47="","",COUNTA($B$5:B47))
A48: =IF(B48="","",COUNTA($B$5:B48))
A49: =IF(B49="","",COUNTA($B$5:B49))
A50: =IF(B50="","",COUNTA($B$5:B50))
...

Sheet Resumo
A1: Resumo dos problemas encontrados
A2: Calculado automaticamente a partir da folha Problemas — não editar.
A4: Tabela | B4: Alta | C4: Média | D4: Baixa | E4: Total | F4: Registos afetados
A5: invoices | B5: =COUNTIFS(Problemas!$B$5:$B$154,$A5,Problemas!$I$5:$I$154,"Alta") -> 3 | C5: =COUNTIFS(Problemas!$B$5:$B$154,$A5,Problemas!$I$5:$I$154,"Média") -> 2 | D5: =COUNTIFS(Problemas!$B$5:$B$154,$A5,Problemas!$I$5:$I$154,"Baixa") -> 3 | E5: =COUNTIF(Problemas!$B$5:$B$154,$A5) -> 8 | F5: =SUMIF(Problemas!$B$5:$B$154,$A5,Problemas!$G$5:$G$154) -> 132
A6: invoices_lines | B6: =COUNTIFS(Problemas!$B$5:$B$154,$A6,Problemas!$I$5:$I$154,"Alta") -> 2 | C6: =COUNTIFS(Problemas!$B$5:$B$154,$A6,Problemas!$I$5:$I$154,"Média") -> 2 | D6: =COUNTIFS(Problemas!$B$5:$B$154,$A6,Problemas!$I$5:$I$154,"Baixa") -> 3 | E6: =COUNTIF(Problemas!$B$5:$B$154,$A6) -> 7 | F6: =SUMIF(Problemas!$B$5:$B$154,$A6,Problemas!$G$5:$G$154) -> 204
A7: customers | B7: =COUNTIFS(Problemas!$B$5:$B$154,$A7,Problemas!$I$5:$I$154,"Alta") -> 4 | C7: =COUNTIFS(Problemas!$B$5:$B$154,$A7,Problemas!$I$5:$I$154,"Média") -> 3 | D7: =COUNTIFS(Problemas!$B$5:$B$154,$A7,Problemas!$I$5:$I$154,"Baixa") -> 13 | E7: =COUNTIF(Problemas!$B$5:$B$154,$A7) -> 20 | F7: =SUMIF(Problemas!$B$5:$B$154,$A7,Problemas!$G$5:$G$154) -> 124
A8: products | B8: =COUNTIFS(Problemas!$B$5:$B$154,$A8,Problemas!$I$5:$I$154,"Alta") -> 0 | C8: =COUNTIFS(Problemas!$B$5:$B$154,$A8,Problemas!$I$5:$I$154,"Média") -> 0 | D8: =COUNTIFS(Problemas!$B$5:$B$154,$A8,Problemas!$I$5:$I$154,"Baixa") -> 0 | E8: =COUNTIF(Problemas!$B$5:$B$154,$A8) -> 0 | F8: =SUMIF(Problemas!$B$5:$B$154,$A8,Problemas!$G$5:$G$154) -> 0
A9: families | B9: =COUNTIFS(Problemas!$B$5:$B$154,$A9,Problemas!$I$5:$I$154,"Alta") -> 0 | C9: =COUNTIFS(Problemas!$B$5:$B$154,$A9,Problemas!$I$5:$I$154,"Média") -> 2 | D9: =COUNTIFS(Problemas!$B$5:$B$154,$A9,Problemas!$I$5:$I$154,"Baixa") -> 2 | E9: =COUNTIF(Problemas!$B$5:$B$154,$A9) -> 4 | F9: =SUMIF(Problemas!$B$5:$B$154,$A9,Problemas!$G$5:$G$154) -> 30
A10: categories | B10: =COUNTIFS(Problemas!$B$5:$B$154,$A10,Problemas!$I$5:$I$154,"Alta") -> 0 | C10: =COUNTIFS(Problemas!$B$5:$B$154,$A10,Problemas!$I$5:$I$154,"Média") -> 0 | D10: =COUNTIFS(Problemas!$B$5:$B$154,$A10,Problemas!$I$5:$I$154,"Baixa") -> 1 | E10: =COUNTIF(Problemas!$B$5:$B$154,$A10) -> 1 | F10: =SUMIF(Problemas!$B$5:$B$154,$A10,Problemas!$G$5:$G$154) -> 2
A11: suplliers | B11: =COUNTIFS(Problemas!$B$5:$B$154,$A11,Problemas!$I$5:$I$154,"Alta") -> 0 | C11: =COUNTIFS(Problemas!$B$5:$B$154,$A11,Problemas!$I$5:$I$154,"Média") -> 0 | D11: =COUNTIFS(Problemas!$B$5:$B$154,$A11,Problemas!$I$5:$I$154,"Baixa") -> 0 | E11: =COUNTIF(Problemas!$B$5:$B$154,$A11) -> 0 | F11: =SUMIF(Problemas!$B$5:$B$154,$A11,Problemas!$G$5:$G$154) -> 0
A12: employees | B12: =COUNTIFS(Problemas!$B$5:$B$154,$A12,Problemas!$I$5:$I$154,"Alta") -> 0 | C12: =COUNTIFS(Problemas!$B$5:$B$154,$A12,Problemas!$I$5:$I$154,"Média") -> 0 | D12: =COUNTIFS(Problemas!$B$5:$B$154,$A12,Problemas!$I$5:$I$154,"Baixa") -> 0 | E12: =COUNTIF(Problemas!$B$5:$B$154,$A12) -> 0 | F12: =SUMIF(Problemas!$B$5:$B$154,$A12,Problemas!$G$5:$G$154) -> 0
A13: zones | B13: =COUNTIFS(Problemas!$B$5:$B$154,$A13,Problemas!$I$5:$I$154,"Alta") -> 0 | C13: =COUNTIFS(Problemas!$B$5:$B$154,$A13,Problemas!$I$5:$I$154,"Média") -> 0 | D13: =COUNTIFS(Problemas!$B$5:$B$154,$A13,Problemas!$I$5:$I$154,"Baixa") -> 0 | E13: =COUNTIF(Problemas!$B$5:$B$154,$A13) -> 0 | F13: =SUMIF(Problemas!$B$5:$B$154,$A13,Problemas!$G$5:$G$154) -> 0
A14: Total | B14: =SUM(B5:B13) -> 9 | C14: =SUM(C5:C13) -> 9 | D14: =SUM(D5:D13) -> 22 | E14: =SUM(E5:E13) -> 40 | F14: =SUM(F5:F13) -> 492
A17: Tipo de problema | B17: Nº problemas | C17: Automatizáveis | D17: Para tabela de erros
A18: Valor em falta | B18: =COUNTIF(Problemas!$H$5:$H$154,$A18) -> 10 | C18: =COUNTIFS(Problemas!$H$5:$H$154,$A18,Problemas!$J$5:$J$154,"Sim") -> 10 | D18: =COUNTIFS(Problemas!$H$5:$H$154,$A18,Problemas!$L$5:$L$154,"Tabela de erros (SA)") -> 0
A19: Violação de domínio | B19: =COUNTIF(Problemas!$H$5:$H$154,$A19) -> 5 | C19: =COUNTIFS(Problemas!$H$5:$H$154,$A19,Problemas!$J$5:$J$154,"Sim") -> 4 | D19: =COUNTIFS(Problemas!$H$5:$H$154,$A19,Problemas!$L$5:$L$154,"Tabela de erros (SA)") -> 0
A20: Formato inválido | B20: =COUNTIF(Problemas!$H$5:$H$154,$A20) -> 6 | C20: =COUNTIFS(Problemas!$H$5:$H$154,$A20,Problemas!$J$5:$J$154,"Sim") -> 4 | D20: =COUNTIFS(Problemas!$H$5:$H$154,$A20,Problemas!$L$5:$L$154,"Tabela de erros (SA)") -> 0
A21: Grafia inconsistente | B21: =COUNTIF(Problemas!$H$5:$H$154,$A21) -> 4 | C21: =COUNTIFS(Problemas!$H$5:$H$154,$A21,Problemas!$J$5:$J$154,"Sim") -> 3 | D21: =COUNTIFS(Problemas!$H$5:$H$154,$A21,Problemas!$L$5:$L$154,"Tabela de erros (SA)") -> 0
A22: Integridade referencial | B22: =COUNTIF(Problemas!$H$5:$H$154,$A22) -> 2 | C22: =COUNTIFS(Problemas!$H$5:$H$154,$A22,Problemas!$J$5:$J$154,"Sim") -> 1 | D22: =COUNTIFS(Problemas!$H$5:$H$154,$A22,Problemas!$L$5:$L$154,"Tabela de erros (SA)") -> 0
A23: Inconsistência entre atributos | B23: =COUNTIF(Problemas!$H$5:$H$154,$A23) -> 8 | C23: =COUNTIFS(Problemas!$H$5:$H$154,$A23,Problemas!$J$5:$J$154,"Sim") -> 5 | D23: =COUNTIFS(Problemas!$H$5:$H$154,$A23,Problemas!$L$5:$L$154,"Tabela de erros (SA)") -> 1
A24: Duplicado exato | B24: =COUNTIF(Problemas!$H$5:$H$154,$A24) -> 1 | C24: =COUNTIFS(Problemas!$H$5:$H$154,$A24,Problemas!$J$5:$J$154,"Sim") -> 1 | D24: =COUNTIFS(Problemas!$H$5:$H$154,$A24,Problemas!$L$5:$L$154,"Tabela de erros (SA)") -> 0
A25: Duplicado aproximado | B25: =COUNTIF(Problemas!$H$5:$H$154,$A25) -> 2 | C25: =COUNTIFS(Problemas!$H$5:$H$154,$A25,Problemas!$J$5:$J$154,"Sim") -> 2 | D25: =COUNTIFS(Problemas!$H$5:$H$154,$A25,Problemas!$L$5:$L$154,"Tabela de erros (SA)") -> 0
A26: Regra de negócio | B26: =COUNTIF(Problemas!$H$5:$H$154,$A26) -> 2 | C26: =COUNTIFS(Problemas!$H$5:$H$154,$A26,Problemas!$J$5:$J$154,"Sim") -> 0 | D26: =COUNTIFS(Problemas!$H$5:$H$154,$A26,Problemas!$L$5:$L$154,"Tabela de erros (SA)") -> 0
A27: Total | B27: =SUM(B18:B26) -> 40 | C27: =SUM(C18:C26) -> 30 | D27: =SUM(D18:D26) -> 1

Sheet Guia
A1: Guia de preenchimento
A3: Coluna | B3: O que escrever | C3: Exemplo
A4: Tabela / Coluna | B4: Tabela e atributo da base MoreRhythm onde está o problema (lista pendente na Tabela). | C4: customers / zone
A5: Perfil / origem | B5: Perfil da Data Profiling Task onde o detetaram, ou "Consulta SQL" se foi por query. | C5: Column Null Ratio
A6: Problema detetado | B6: Descrição curta e objetiva do problema. | C6: Zona em falta
A7: Exemplo | B7: Valor concreto ou ID do registo afetado, para evidência no relatório. | C7: cliente 2 'Vendas a Dinheiro'
A8: Nº registos afetados | B8: Quantos registos têm o problema (número inteiro). | C8: 2
A9: Tipo de problema | B9: Valor em falta · Violação de domínio · Formato inválido · Integridade referencial · Inconsistência entre atributos · Duplicado exato · Duplicado aproximado. | C9: Valor em falta
A10: Gravidade | B10: Alta = afeta factos/medidas ou FKs · Média = afeta atributos de análise · Baixa = atributo descritivo pouco relevante. | C10: Média
A11: Correção automatizável? | B11: Sim se o ETL consegue corrigir sem intervenção humana (ex.: TRIM, valor por omissão, deduplicação). Não caso contrário. | C11: Não
A12: Ação proposta | B12: O que o ETL vai fazer: corrigir, substituir por valor "Desconhecido", agrupar duplicados, enviar para tabela de erros… | C12: Atribuir membro "Desconhecido" na dimensão
A13: Destino do registo | B13: Corrigir no ETL · Tabela de erros (SA) · Manter / sem ação. O enunciado exige que o que não for corrigível vá para tabelas de erros na Staging Area. | C13: Corrigir no ETL

Sheet Notas
A1: Notas da análise (observações que não são problemas)
A3: Tabela | B3: Nota | C3: Evidência
A4: customers | B4: A coluna number (PK) não aparece no Candidate Key Profile: o perfil não suporta o tipo numeric. A unicidade foi verificada por SQL e é garantida pela PK PK_clientes_1. | C4: SELECT COUNT(*), COUNT(DISTINCT number) FROM customers → 26 / 26
A5: customers | B5: create_time e last_update_date aparecem com 100% de unicidade no Candidate Key apenas por coincidência (amostra pequena); não têm significado como chave. | C5: Candidate Key Profile
A6: customers | B6: O NIF não é suficiente como regra de deduplicação: identifica o duplicado exato, mas não os aproximados (NIF com dígitos trocados). É necessária comparação aproximada (Fuzzy Grouping) sobre vários atributos. | C6: Pares 8/22 e 5/26
A7: customers | B7: O segment tem só 3 valores (Alto, Médio, Baixo), escritos de forma consistente: sem problemas. | C7: Column Value Distribution
A8: customers | B8: O Pattern Profile do email não generaliza com poucos registos (cada email é um padrão); a validação foi complementada por SQL. | C8: SELECT … WHERE email NOT LIKE '%_@_%._%'
A9: customers | B9: Não há registos com last_update anterior a create (datas de auditoria consistentes nesta tabela). | C9: Consulta SQL
A10: customers | B10: Regra para a tabela de erros da Staging Area (cargas futuras): cliente sem number ou sem name → tabela de erros. Na amostra não há casos. | C10: Regra proposta
A11: invoices_lines | B11: Sem NULLs nem valores vazios em nenhuma coluna; invoice_line_stamp_id é 100% único (Candidate Key). | C11: Null Ratio + Candidate Key
A12: invoices_lines | B12: Integridade referencial completa: todas as linhas têm fatura e produto existentes; nenhuma linha refere os produtos com atributos a NULL (Z001, CORSR). | C12: Consulta SQL c)
A13: invoices_lines | B13: Em valor absoluto, quantity × unit_price = line_total em todas as 93 linhas, e line_vat = 23% de line_total em todas (todos os produtos têm vat_rate 23). | C13: Consultas SQL a) e b)
A14: invoices_lines | B14: As quantidades são todas inteiras, apesar de o tipo ser numeric(14,4). 34 produtos distintos vendidos (de 67); 1 a 5 linhas por fatura; nenhum produto repetido na mesma fatura. | C14: Column Statistics + SQL
... A33: categories | B33: "Peças" e "Pilhas" existem simultaneamente como categoria, como família/classificação ou como classification dos produtos. Convém nomear claramente os atributos na dimensão para evitar confusão nas análises. | C33: Comparação entre tabelas

Sheet Listas
A1: Tabela | B1: Perfil | C1: Tipo | D1: Gravidade | E1: Automatizavel | F1: Destino
A2: invoices | B2: Column Null Ratio | C2: Valor em falta | D2: Alta | E2: Sim | F2: Corrigir no ETL
A3: invoices_lines | B3: Column Value Distribution | C3: Violação de domínio | D3: Média | E3: Não | F3: Tabela de erros (SA)
A4: customers | B4: Column Length Distribution | C4: Formato inválido | D4: Baixa | F4: Manter / sem ação
A5: products | B5: Column Pattern | C5: Grafia inconsistente
A6: families | B6: Column Statistics | C6: Integridade referencial
A7: categories | B7: Candidate Key | C7: Inconsistência entre atributos
A8: suplliers | B8: Consulta SQL | C8: Duplicado exato
A9: employees | C9: Duplicado aproximado
A10: zones | C10: Regra de negócio
